Workbook

Sheet Index
A1: NORTH COAL STATE OWNED CORPORATION
A2: ERP FORMS & STANDARD TEMPLATES - PAYROLL MODULE
A3: Developer pack accompanying the approved System Architecture & BPR Report (20 September 2026) | Prepared by Crest Point Consulting Group | Version 1.0
A5: COLOUR LEGEND
A6: Yellow | B6: Field entered by a user (blue text = example data shown for illustration)
A7: Grey | B7: Auto-populated / auto-calculated by the system
A8: Light grey | B8: Not applicable on this form
A9: Navy | B9: Section / column headers and signature-block titles
A11: Form Code | B11: Sheet (click to open) | C11: Purpose | D11: Source in approved report
A12: PY-01 | B12: PY-01 Employee Record | C12: Employee database record (mandatory fields, bank details, date-effective history) | D12: 4.3.2 Employee Database
A13: PY-02 | B13: PY-02 Salary Change Pro-Rata | C13: Automatic mid-month salary / position change pro-rata | D13: 4.3.2 Mid-Month Pro-Rata Adjustments
A14: PY-03 | B14: PY-03 Leave Request | C14: Leave record with balance check and exceptional-leave rules | D14: 4.3.2 Leave Management
A15: PY-04 | B15: PY-04 Leave Balance Summary | C15: Monthly leave balance report per Permanent employee | D15: 4.3.2 Leave Management; 4.3.4 Reports
A16: PY-05 | B16: PY-05 Timesheet | C16: Monthly daily-record timesheet with auto summary | D16: 4.3.2 Timesheet Recording
A17: PY-06 | B17: PY-06 Dept Timesheet Finalize | C17: Department Head month-end review and locking | D17: 4.3.2 Timesheet Finalization by Department Head
A18: PY-07 | B18: PY-07 Salary Advance Request | C18: Advance request, approval chain and recorded advance | D18: 4.3.2 Salary Advance Management
A19: PY-08 | B19: PY-08 Employee Advance Ledger | C19: Advance ledger with limit and balance checks | D19: 4.3.2; 4.3.4 Employee Advance Ledger
A20: PY-09 | B20: PY-09 Payroll Calculation | C20: Payroll sheet for Permanent and Temporary staff (replaces Forms M-41 / M-40) | D20: 4.3.2 Payroll Calculation; Net Pay Calculation
A21: PY-10 | B21: PY-10 Wages-Based Entry | C21: Collective cash wages total per Second Unit | D21: 4.3.2 Wages-Based Workers
A22: PY-11 | B22: PY-11 Payroll Summary | C22: Consolidated record sent to IC for the single verification | D22: 4.3.2 Payroll Sheet Finalization
... A31: PY-20 | B31: PY-20 Reports Spec | C31: Required payroll reports, frequency and filters | D31: 4.3.4 Required Reports
A33: DESIGN RULES THAT APPLY TO EVERY FORM
A34: 1. Single currency: Afghan Afghani (AFN) only.
A35: 2. Three staff categories: Permanent (leave system, full payroll), Temporary (paid only when present, no leave), Wages-based workers (collective cash total per Second Unit, not recorded as named individuals).
A36: 3. Executive Director and Directors have NO system access. Their approvals (leave letters, advances, the printed payroll sheet) are physical, filed in hard copy and recorded by staff, so no Director / ED signature block appears on these forms.
A37: 4. Signature blocks: Prepared by (Payroll Officer), Reviewed / Approved by (Payroll Department Head), Verified by (Internal Control) on the payroll sheet, summary, wages entry and bank list. Internal Control verification is ONE consolidated gate before any accounting entry or payment.
A38: 5. Officers can never edit or delete a submitted entry; corrections follow PY-17. Every action is written to the Control Log (layout FA-18 in the Finance workbook), which no user can alter.
A39: 6. Payroll rules (tax slabs, leave entitlements, overtime rates) must be parameters that authorized users can change without code - the Payroll Manager asked for flexibility if regulations change.
A40: 7. Names, IDs, amounts and rates in these sheets are illustrative examples only. Bank account numbers are masked examples.

Sheet PY-01 Employee Record
A1: [Corporation logo] | C1: NORTH COAL STATE OWNED CORPORATION
C2: EMPLOYEE DATABASE RECORD
C3: Form PY-01 | Version 1.0 | Permanent and Temporary employees only (wages-based workers are not recorded individually)
A5: A. EMPLOYEE DETAILS (all fields mandatory)
A6: Employee ID | C6: EMP-000101 | D6: Status | E6: Active
A7: Full Name | C7: Example Employee A | D7: Father's Name | E7: Example Father A
A8: Position | C8: Finance Officer | D8: Department | E8: Finance
A9: Employment Type | C9: Permanent | D9: Second Unit / HQ Assignment | E9: HQ
A10: Joining Date | C10: 45352 | D10: Basic Salary (AFN per month) | E10: 40000
A12: B. BANK ACCOUNT DETAILS (Permanent and Temporary staff only)
A13: Bank Name | C13: Example Bank | D13: Account Number (masked example) | E13: XXXX-XXXX-0000
A15: C. DATE-EFFECTIVE SALARY AND POSITION HISTORY
A16: No. | B16: Effective Date | C16: Position | D16: Change Type | E16: Basic Salary (AFN) | F16: Recorded By
A17: 1 | B17: 45352 | C17: Finance Assistant | D17: Initial | E17: 30000 | F17: USER-01
A18: 2 | B18: 46023 | C18: Finance Officer | D18: Position and salary change | E18: 40000 | F18: USER-01
A19: 3
A20: 4
A22: PREPARED BY (Record maintainer) | D22: REVIEWED BY (Payroll Department Head)
A23: Name: | D23: Name:
A24: Position: | D24: Position:
A25: Signature: | D25: Signature:
A26: Date: | D26: Date:
A28: NOTES FOR DEVELOPERS
A29: 1. Mandatory fields per the approved design: full name, father's name, position, department, employment type, Second Unit/HQ, joining date, basic salary, bank account details (Permanent and Temporary only), active/inactive status.
A30: 2. Salary and position changes are DATE-EFFECTIVE so payroll can pro-rate mid-month changes automatically (see PY-02).
A31: 3. Wages-based workers are not recorded here; their pay is entered as a collective cash total per Second Unit (PY-10).
A32: 4. The approved report does not name which role maintains the Employee Database (HR or Payroll) or who approves new records - confirm before development. Employee ID is a system reference added for uniqueness.

Sheet PY-02 Salary Change Pro-Rata
A1: [Corporation logo] | C1: NORTH COAL STATE OWNED CORPORATION
C2: MID-MONTH SALARY / POSITION CHANGE - PRO-RATA CALCULATION
C3: Form PY-02 | Version 1.0 | Calculated automatically during monthly payroll
A5: A. CHANGE DETAILS (from Employee Database)
A6: Employee Name | C6: Example Employee A | D6: Employee ID | E6: EMP-000101
A7: Change Type | C7: Basic salary | D7: Effective Date of Change | E7: 46347
A8: Old Position | C8: Finance Officer | D8: New Position | E8: Senior Finance Officer
A9: Old Basic Salary (AFN) | C9: 40000 | D9: New Basic Salary (AFN) | E9: 50000
A11: B. AUTOMATIC PRO-RATA
A12: Payroll Month (first day) | C12: 46327 | D12: Days in Month | E12: =DAY(EOMONTH(C12,0)) -> 30
A13: Days at Old Salary | C13: =MAX(0,MIN(E12,E7-C12)) -> 20 | D13: Days at New Salary | E13: =E12-C13 -> 10
A14: Old-Salary Portion (AFN) | C14: =ROUND(C9*C13/E12,2) -> 26666.67 | D14: New-Salary Portion (AFN) | E14: =ROUND(E9*E13/E12,2) -> 16666.67
A15: Gross Basic Salary for the Month (AFN) | C15: =ROUND(C9*C13/E12+E9*E13/E12,2) -> 43333.33
A17: PREPARED BY (Payroll Officer) | D17: REVIEWED BY (Payroll Department Head)
A18: Name: | D18: Name:
A19: Position: | D19: Position:
A20: Signature: | D20: Signature:
A21: Date: | D21: Date:
A23: NOTES FOR DEVELOPERS
A24: 1. Rule from the approved report: in a 30-day month a change effective on the 21st gives 20 days at the old basic salary and 10 days at the new one, merged into one correct Gross Basic Salary. The example above reproduces exactly that.
A25: 2. The result feeds the "Basic Salary" column of the payroll calculation sheet (PY-09) - the Payroll Officer does not key it manually.
A26: 3. Pro-rata is by calendar days of the month, as in the report example. Position changes follow the same date-effective logic so history stays traceable.

Sheet PY-03 Leave Request
A1: [Corporation logo] | C1: NORTH COAL STATE OWNED CORPORATION
C2: LEAVE RECORD (PERMANENT EMPLOYEES ONLY)
C3: Form PY-03 | Version 1.0 | Recorded in the system by the Department Head from the physically approved letter
A5: A. LEAVE DETAILS
A6: Leave Record No. | C6: LV-2026-000187 | D6: Date Recorded | E6: 46300
A7: Employee Name | C7: Example Employee A | D7: Employee ID | E7: EMP-000101
A8: Department | C8: Finance | D8: Employment Type | E8: Permanent
A9: Leave Type | C9: Annual Leave | D9: Director Physical Approval Ref. (hard file) | E9: DIR-LV-2026-0310
A10: Start Date | C10: 46313 | D10: End Date | E10: 46317
A11: Number of Days (per approved letter) | C11: 5 | D11: Recorded By | E11: Department Head
A12: B. AUTOMATIC BALANCE CHECK
A13: Annual Entitlement (this leave type) | C13: =IF(C9="Other / Exceptional Leave","As approved",INDEX(C23:C26,MATCH(C9,A23:A26,0))) -> 20 | D13: Days Already Taken This Year | E13: 8
A14: Available Balance (days) | C14: =IF(C9="Other / Exceptional Leave","n/a",C13-E13) -> 12 | D14: Days Requested | E14: =C11 -> 5
A15: C. EXCEPTIONAL LEAVE ONLY (beyond the 50-day standard entitlement)
A16: Written Justification (mandatory)
A17: Specific Director Physical Approval Ref. (mandatory) | D17: Confirmation Recorded On
A18: D. SYSTEM DECISION
A19: Result | C19: =IF(E8<>"Permanent","BLOCKED - leave management applies to Permanent employees only",IF(C9="Other / Exceptional Leave",IF(AND(C16<>"",C17<>""),"ACCEPTED - standard balance limit bypassed; reflected in the timesheet","BLOCKED - written justification and Director-level approval confirmation are mandatory"),IF(C11<=C14,"ACCEPTED - balance updated in real time; reflected in the timesheet","BLOCKED - insufficient balance; use Other / Exceptional Leave"))) -> ACCEPTED - balance updated in real time; reflected in the timesheet
A21: LEAVE ENTITLEMENT PARAMETERS (configurable) | D21: Annual Entitlement (days)
A22: Leave Type | D22: Days
A23: Annual Leave | C23: 20
A24: Urgency Leave | C24: 10
A25: Sick Leave | C25: 20
A26: Other / Exceptional Leave | C26: As approved
A27: Total Standard | C27: =SUM(C23:C26) -> 50 | D27: days per Permanent employee per year
A29: REQUESTED BY (Employee) | D29: RECORDED BY (Department Head)
A30: Name: | D30: Name:
A31: Position: | D31: Position:
A32: Signature: | D32: Signature:
A33: Date: | D33: Date:
A35: NOTES FOR DEVELOPERS
A36: 1. Process: employee submits a hard-copy letter -> relevant Director approves physically -> Department Head records name, leave type, start date, end date and days in the ERP. The balance is checked and updated in real time.
A37: 2. Exceptional leave: the system forces a written justification AND a specific Director-level physical approval confirmation before bypassing the balance limit. The finalized record flows into the employee's timesheet automatically.
A38: 3. Temporary employees and wages-based workers have no leave entitlement (paid when present, unpaid when absent).
A39: 4. The Executive Director and Directors have no system access. Their approvals (leave letters, advances, the printed payroll sheet) are physical, filed in hard copy and recorded in the ERP by staff, so no Director signature block appears on these forms.

Sheet PY-04 Leave Balance Summary
A1: [Corporation logo] | C1: NORTH COAL STATE OWNED CORPORATION
C2: MONTHLY LEAVE BALANCE SUMMARY - PERMANENT EMPLOYEES
C3: Report layout feeding the monthly timesheet used for payroll
A5: Month | C5: October 2026 | F5: Generated On / By | I5: 14-Oct-2026 10:15 / PAY-HEAD-01
D7: Annual Leave (entitlement 20) | G7: Urgency Leave (entitlement 10) | J7: Sick Leave (entitlement 20) | M7: Totals
A8: Employee ID | B8: Employee Name | C8: Department | D8: Opening | E8: Taken | F8: Closing | G8: Opening | H8: Taken | I8: Closing | J8: Opening | K8: Taken | L8: Closing | M8: Other / Exceptional Taken | N8: Total Days Taken | O8: Total Standard Closing Balance
A9: EMP-000101 | B9: Example Employee A | C9: Finance | D9: 20 | E9: 5 | F9: =IF(D9="","",D9-E9) -> 15 | G9: 10 | H9: 0 | I9: =IF(G9="","",G9-H9) -> 10 | J9: 20 | K9: 2 | L9: =IF(J9="","",J9-K9) -> 18 | M9: 0 | N9: =IF(A9="","",E9+H9+K9+M9) -> 7 | O9: =IF(A9="","",F9+I9+L9) -> 43
A10: EMP-000118 | B10: Example Employee E | C10: Administration | D10: 20 | E10: 0 | F10: =IF(D10="","",D10-E10) -> 20 | G10: 10 | H10: 1 | I10: =IF(G10="","",G10-H10) -> 9 | J10: 20 | K10: 0 | L10: =IF(J10="","",J10-K10) -> 20 | M10: 0 | N10: =IF(A10="","",E10+H10+K10+M10) -> 1 | O10: =IF(A10="","",F10+I10+L10) -> 49
A11: EMP-000124 | B11: Example Employee F | C11: HQ Operations | D11: 20 | E11: 12 | F11: =IF(D11="","",D11-E11) -> 8 | G11: 10 | H11: 0 | I11: =IF(G11="","",G11-H11) -> 10 | J11: 20 | K11: 6 | L11: =IF(J11="","",J11-K11) -> 14 | M11: 3 | N11: =IF(A11="","",E11+H11+K11+M11) -> 21 | O11: =IF(A11="","",F11+I11+L11) -> 32
F12: =IF(D12="","",D12-E12) | I12: =IF(G12="","",G12-H12) | L12: =IF(J12="","",J12-K12) | N12: =IF(A12="","",E12+H12+K12+M12) | O12: =IF(A12="","",F12+I12+L12)
F13: =IF(D13="","",D13-E13) | I13: =IF(G13="","",G13-H13) | L13: =IF(J13="","",J13-K13) | N13: =IF(A13="","",E13+H13+K13+M13) | O13: =IF(A13="","",F13+I13+L13)
F14: =IF(D14="","",D14-E14) | I14: =IF(G14="","",G14-H14) | L14: =IF(J14="","",J14-K14) | N14: =IF(A14="","",E14+H14+K14+M14) | O14: =IF(A14="","",F14+I14+L14)
F15: =IF(D15="","",D15-E15) | I15: =IF(G15="","",G15-H15) | L15: =IF(J15="","",J15-K15) | N15: =IF(A15="","",E15+H15+K15+M15) | O15: =IF(A15="","",F15+I15+L15)
F16: =IF(D16="","",D16-E16) | I16: =IF(G16="","",G16-H16) | L16: =IF(J16="","",J16-K16) | N16: =IF(A16="","",E16+H16+K16+M16) | O16: =IF(A16="","",F16+I16+L16)
F17: =IF(D17="","",D17-E17) | I17: =IF(G17="","",G17-H17) | L17: =IF(J17="","",J17-K17) | N17: =IF(A17="","",E17+H17+K17+M17) | O17: =IF(A17="","",F17+I17+L17)
F18: =IF(D18="","",D18-E18) | I18: =IF(G18="","",G18-H18) | L18: =IF(J18="","",J18-K18) | N18: =IF(A18="","",E18+H18+K18+M18) | O18: =IF(A18="","",F18+I18+L18)
A20: NOTES FOR DEVELOPERS
A21: 1. Opening balance resets at the start of each year (20 annual + 10 urgency + 20 sick = 50 standard days). Closing = Opening - Taken for each type; exceptional leave is shown separately because it bypasses the standard limit.
A22: 2. Example values are illustrative. Standard report header/footer (corporation name, logo, title, date range, timestamp, user) applies; export to PDF and Excel.

Sheet PY-05 Timesheet
A1: [Corporation logo] | C1: NORTH COAL STATE OWNED CORPORATION
C2: MONTHLY TIMESHEET
C3: Form PY-05 | Version 1.0 | One per employee per month (Permanent, Temporary and wages-based staff)
A5: A. EMPLOYEE AND PERIOD
A6: Employee Name | B6: Example Employee A | D6: Employee ID | E6: EMP-000101
A7: Department | B7: Finance | D7: Employment Type | E7: Permanent
A8: Month | B8: October 2026 | D8: Second Unit / HQ | E8: HQ
A9: Entered By | B9: Self (individual access) | D9: Timesheet Status | E9: Draft
A11: B. DAILY RECORD
A12: Date | B12: Day | C12: Status | D12: Regular Hours | E12: Overtime Hours | F12: Notes (optional)
A13: 46296 | B13: =TEXT(A13,"dddd") -> Thursday | C13: Present | D13: 8 | E13: 0
A14: =A13+1 -> 46297 | B14: =TEXT(A14,"dddd") -> Friday
A15: =A14+1 -> 46298 | B15: =TEXT(A15,"dddd") -> Saturday | C15: Present | D15: 8 | E15: 0
A16: =A15+1 -> 46299 | B16: =TEXT(A16,"dddd") -> Sunday | C16: Present | D16: 8 | E16: 0
A17: =A16+1 -> 46300 | B17: =TEXT(A17,"dddd") -> Monday | C17: Present | D17: 8 | E17: 0
A18: =A17+1 -> 46301 | B18: =TEXT(A18,"dddd") -> Tuesday | C18: Present | D18: 8 | E18: 0
A19: =A18+1 -> 46302 | B19: =TEXT(A19,"dddd") -> Wednesday | C19: Annual Leave | D19: 0 | E19: 0 | F19: Leave LV-2026-000187 (example)
A20: =A19+1 -> 46303 | B20: =TEXT(A20,"dddd") -> Thursday | C20: Annual Leave | D20: 0 | E20: 0
A21: =A20+1 -> 46304 | B21: =TEXT(A21,"dddd") -> Friday
A22: =A21+1 -> 46305 | B22: =TEXT(A22,"dddd") -> Saturday | C22: Present | D22: 8 | E22: 0
A23: =A22+1 -> 46306 | B23: =TEXT(A23,"dddd") -> Sunday | C23: Present | D23: 8 | E23: 0
A24: =A23+1 -> 46307 | B24: =TEXT(A24,"dddd") -> Monday | C24: Field Work | D24: 8 | E24: 0 | F24: Site visit
A25: =A24+1 -> 46308 | B25: =TEXT(A25,"dddd") -> Tuesday | C25: Field Work | D25: 8 | E25: 1
A26: =A25+1 -> 46309 | B26: =TEXT(A26,"dddd") -> Wednesday | C26: Official Travel | D26: 8 | E26: 2 | F26: Travel to Second Unit A
A27: =A26+1 -> 46310 | B27: =TEXT(A27,"dddd") -> Thursday | C27: Present | D27: 8 | E27: 0
A28: =A27+1 -> 46311 | B28: =TEXT(A28,"dddd") -> Friday
A29: =A28+1 -> 46312 | B29: =TEXT(A29,"dddd") -> Saturday | C29: Present | D29: 8 | E29: 0
A30: =A29+1 -> 46313 | B30: =TEXT(A30,"dddd") -> Sunday | C30: Present | D30: 8 | E30: 0
A31: =A30+1 -> 46314 | B31: =TEXT(A31,"dddd") -> Monday | C31: Present | D31: 8 | E31: 0
A32: =A31+1 -> 46315 | B32: =TEXT(A32,"dddd") -> Tuesday | C32: Sick Leave | D32: 0 | E32: 0 | F32: Medical leave
A33: =A32+1 -> 46316 | B33: =TEXT(A33,"dddd") -> Wednesday | C33: Present | D33: 8 | E33: 3 | F33: Month-end closing
A34: =A33+1 -> 46317 | B34: =TEXT(A34,"dddd") -> Thursday | C34: Absent | D34: 0 | E34: 0 | F34: Unexcused
A35: =A34+1 -> 46318 | B35: =TEXT(A35,"dddd") -> Friday
A36: =A35+1 -> 46319 | B36: =TEXT(A36,"dddd") -> Saturday | C36: Present | D36: 8 | E36: 0
A37: =A36+1 -> 46320 | B37: =TEXT(A37,"dddd") -> Sunday | C37: Present | D37: 8 | E37: 0
A38: =A37+1 -> 46321 | B38: =TEXT(A38,"dddd") -> Monday | C38: Present | D38: 8 | E38: 0
A39: =A38+1 -> 46322 | B39: =TEXT(A39,"dddd") -> Tuesday | C39: Present | D39: 8 | E39: 0
A40: =A39+1 -> 46323 | B40: =TEXT(A40,"dddd") -> Wednesday | C40: Present | D40: 8 | E40: 0
A41: =A40+1 -> 46324 | B41: =TEXT(A41,"dddd") -> Thursday | C41: Present | D41: 8 | E41: 0
A42: =A41+1 -> 46325 | B42: =TEXT(A42,"dddd") -> Friday
...

Sheet PY-06 Dept Timesheet Finalize
A1: [Corporation logo] | C1: NORTH COAL STATE OWNED CORPORATION
C2: DEPARTMENT TIMESHEET REVIEW AND FINALIZATION
C3: Form PY-06 | Version 1.0 | Month-end submission by the Department Head - locks the timesheets
A5: Department | C5: Finance | F5: Month | I5: October 2026
A6: Second Unit / HQ | C6: HQ | F6: Submission Status | I6: Submitted - locked and routed to Payroll
A8: Employee ID | B8: Employee Name | C8: Employment Type | D8: Days Present | E8: Field Work Days | F8: Official Travel Days | G8: Absent Days | H8: Leave Days (all types) | I8: Regular Hours | J8: Overtime Hours | K8: Department Head Remarks
A9: EMP-000101 | B9: Example Employee A | C9: Permanent | D9: 20 | E9: 2 | F9: 1 | G9: 1 | H9: 3 | I9: 176 | J9: 6
A10: EMP-000118 | B10: Example Employee E | C10: Permanent | D10: 24 | E10: 0 | F10: 0 | G10: 0 | H10: 1 | I10: 192 | J10: 0
A11: EMP-000131 | B11: Example Employee G | C11: Temporary | D11: 22 | E11: 0 | F11: 0 | G11: 2 | H11: 0 | I11: 176 | J11: 4
A19: TOTAL | D19: =SUM(D9:D18) -> 66 | E19: =SUM(E9:E18) -> 2 | F19: =SUM(F9:F18) -> 1 | G19: =SUM(G9:G18) -> 3 | H19: =SUM(H9:H18) -> 4 | I19: =SUM(I9:I18) -> 544 | J19: =SUM(J9:J18) -> 10
A21: PREPARED BY (Designated Timesheet Officer) | E21: FINALIZED BY (Department Head)
A22: Name: | E22: Name:
A23: Position: | E23: Position:
A24: Signature: | E24: Signature:
A25: Date: | E25: Date:
A27: NOTES FOR DEVELOPERS
A28: 1. The Department Head reviews leave taken, absences, field work days, official travel days and overtime hours for the whole department before submitting.
A29: 2. Once submitted the timesheet record is locked and routed automatically to the Payroll module. Corrections after locking follow the Correction Request workflow (PY-17).

Sheet PY-07 Salary Advance Request
A1: [Corporation logo] | C1: NORTH COAL STATE OWNED CORPORATION
C2: SALARY ADVANCE REQUEST
C3: Form PY-07 | Version 1.0 | Submitted by the Department Head; paid through a Finance Payment Voucher
A5: A. REQUEST (submitted by Department Head)
A6: Advance Request No. | C6: SA-2026-000019 | D6: Date Submitted | E6: 46298
A7: Employee Name | C7: Example Employee A | D7: Employee ID | E7: EMP-000101
A8: Department | C8: Finance | D8: Second Unit / HQ | E8: HQ
A9: Amount Requested (AFN) | C9: 60000 | D9: Proposed Monthly Deduction Limit (AFN) | E9: 10000
A10: Reason | C10: Family emergency expenses. EXAMPLE DATA.
A11: Months to Recover (auto) | C11: =IF(E9>0,ROUNDUP(C9/E9,0),"") -> 6 | D11: Request Status | E11: Authorized - paid
A13: B. APPROVAL CHAIN
A14: Department Head Confirmation (system) | C14: Confirmed | D14: Date | E14: 46298
A15: Director Physical Approval Ref. (hard file) | C15: DIR-ADV-2026-0072 | D15: Director Approval Date (physical) | E15: 46299
A16: Confirmation Recorded in ERP By | C16: Payroll / department staff | D16: Recorded On | E16: 46299.431
A17: Finance Dept Head Authorization | C17: Approved | D17: Authorization Date | E17: 46300
A18: Finance Payment Voucher Ref. | C18: PV-000118 | D18: Payment Date | E18: 46301
A20: C. ADVANCE RECORDED AGAINST EMPLOYEE (auto)
A21: Total Advance Amount (AFN) | C21: =C9 -> 60000 | D21: Approved Max Monthly Deduction (AFN) | E21: =E9 -> 10000
A22: Outstanding Balance (AFN) | C22: =C21 -> 60000 | D22: Recovery Notification | E22: Shown to Payroll Officer every payroll until fully recovered
A24: SUBMITTED BY (Department Head) | D24: AUTHORIZED BY (Finance Department Head)
A25: Name: | D25: Name:
A26: Position: | D26: Position:
A27: Signature: | D27: Signature:
A28: Date: | D28: Date:
A30: NOTES FOR DEVELOPERS
A31: 1. Sequence: Department Head submits (employee, amount, reason, proposed monthly deduction limit) -> Department Head confirms in system -> Director physical approval recorded by staff -> Finance Department Head authorizes -> payment via Finance PV (see FA-01).
A32: 2. After payment the advance is recorded on the employee record with total amount and approved monthly limit; the balance stays visible until fully recovered (ledger: PY-08).
A33: 3. The Executive Director and Directors have no system access. Their approvals (leave letters, advances, the printed payroll sheet) are physical, filed in hard copy and recorded in the ERP by staff, so no Director signature block appears on these forms.

Sheet PY-08 Employee Advance Ledger
A1: [Corporation logo] | C1: NORTH COAL STATE OWNED CORPORATION
C2: EMPLOYEE ADVANCE LEDGER
C3: Report layout - outstanding balance visible at all times until fully recovered
A5: Employee | C5: Example Employee A (EMP-000101) | E5: Advance Ref. | G5: SA-2026-000019
A6: Total Advance (AFN) | C6: 60000 | E6: Approved Max Monthly Deduction (AFN) | G6: 10000
A8: No. | B8: Date | C8: Reference | D8: Description | E8: Advance Paid (AFN) | F8: Deduction Applied (AFN) | G8: Outstanding Balance (AFN) | H8: Limit Check (auto)
A9: 1 | B9: 46301 | C9: PV-000118 | D9: Advance paid via Payment Voucher | E9: 60000 | G9: =IF(B9="","",N(E9)-N(F9)) -> 60000
A10: 2 | B10: 46326 | C10: PAY-2026-10 | D10: Payroll deduction - October 2026 | F10: 10000 | G10: =IF(B10="","",N(G9)+N(E10)-N(F10)) -> 50000 | H10: =IF(F10="","",IF(F10>$G$6,"EXCEEDS APPROVED LIMIT",IF(F10>N(G9),"EXCEEDS BALANCE","Within limit"))) -> Within limit
A11: 3 | B11: 46356 | C11: PAY-2026-11 | D11: Payroll deduction - November 2026 | F11: 10000 | G11: =IF(B11="","",N(G10)+N(E11)-N(F11)) -> 40000 | H11: =IF(F11="","",IF(F11>$G$6,"EXCEEDS APPROVED LIMIT",IF(F11>N(G10),"EXCEEDS BALANCE","Within limit"))) -> Within limit
A12: 4 | B12: 46387 | C12: PAY-2026-12 | D12: Payroll deduction - December 2026 | F12: 12000 | G12: =IF(B12="","",N(G11)+N(E12)-N(F12)) -> 28000 | H12: =IF(F12="","",IF(F12>$G$6,"EXCEEDS APPROVED LIMIT",IF(F12>N(G11),"EXCEEDS BALANCE","Within limit"))) -> EXCEEDS APPROVED LIMIT
A13: 5 | G13: =IF(B13="","",N(G12)+N(E13)-N(F13)) | H13: =IF(F13="","",IF(F13>$G$6,"EXCEEDS APPROVED LIMIT",IF(F13>N(G12),"EXCEEDS BALANCE","Within limit")))
A14: 6 | G14: =IF(B14="","",N(G13)+N(E14)-N(F14)) | H14: =IF(F14="","",IF(F14>$G$6,"EXCEEDS APPROVED LIMIT",IF(F14>N(G13),"EXCEEDS BALANCE","Within limit")))
A15: 7 | G15: =IF(B15="","",N(G14)+N(E15)-N(F15)) | H15: =IF(F15="","",IF(F15>$G$6,"EXCEEDS APPROVED LIMIT",IF(F15>N(G14),"EXCEEDS BALANCE","Within limit")))
A16: 8 | G16: =IF(B16="","",N(G15)+N(E16)-N(F16)) | H16: =IF(F16="","",IF(F16>$G$6,"EXCEEDS APPROVED LIMIT",IF(F16>N(G15),"EXCEEDS BALANCE","Within limit")))
A17: 9 | G17: =IF(B17="","",N(G16)+N(E17)-N(F17)) | H17: =IF(F17="","",IF(F17>$G$6,"EXCEEDS APPROVED LIMIT",IF(F17>N(G16),"EXCEEDS BALANCE","Within limit")))
A18: 10 | G18: =IF(B18="","",N(G17)+N(E18)-N(F18)) | H18: =IF(F18="","",IF(F18>$G$6,"EXCEEDS APPROVED LIMIT",IF(F18>N(G17),"EXCEEDS BALANCE","Within limit")))
A19: Current outstanding balance (AFN) | G19: =IF(COUNT(G9:G18)=0,0,LOOKUP(9.99E+307,G9:G18)) -> 28000 | H19: =IF(G19=0,"Fully recovered","Outstanding") -> Outstanding
A21: NOTES FOR DEVELOPERS
A22: 1. The Payroll Officer is notified of the outstanding balance and the approved monthly limit at payroll preparation, then keys the month's deduction within the limit; the system reduces the balance automatically.
A23: 2. The December line (12,000) deliberately exceeds the 10,000 limit to show the validation message. Accounting: Dr Salaries Payable / Cr Employee Advance (PY-19).

Sheet PY-09 Payroll Calculation
A1: [Corporation logo] | C1: NORTH COAL STATE OWNED CORPORATION
C2: PAYROLL CALCULATION SHEET - PERMANENT AND TEMPORARY STAFF
C3: Form PY-09 | Version 1.0 | Replaces manual Forms M-41 / M-40 | Amounts in AFN
A5: Payroll Period Ref. | D5: PAY-2026-10-HQ | G5: Payroll Month | L5: October 2026
A6: Scope | D6: HQ - Permanent and Temporary staff | G6: Sheet Status | L6: Pending IC verification
A8: No. | B8: Employee ID | C8: Employee Name | D8: Father's Name | E8: Department | F8: Type | G8: Basic Salary (after pro-rata) | H8: OT Hours (timesheet) | I8: OT Rate (AFN/hr) | J8: Overtime Pay | K8: Other Allowances | L8: Gross Taxable Income | M8: Rent Deduction | N8: Electricity Deduction | O8: Advance Deduction | P8: Advance Outstanding (system) | Q8: Approved Monthly Limit (system) | R8: Income Tax (auto) | S8: Net Pay | T8: Advance Check (auto)
A9: 1 | B9: EMP-000101 | C9: Example Employee A | D9: Example Father A | E9: Finance | F9: Permanent | G9: 40000 | H9: 10 | I9: 250 | J9: =IF(B9="","",ROUND(N(H9)*N(I9),2)) -> 2500 | K9: 3000 | L9: =IF(B9="","",N(G9)+N(J9)+N(K9)) -> 45500 | M9: 2000 | N9: 500 | O9: 10000 | P9: 60000 | Q9: 10000 | R9: =IF(B9="","",ROUND(SUMPRODUCT(('PY-15 Tax Slab Config'!$A$8:$A$11<$L9)*(($L9<'PY-15 Tax Slab Config'!$B$8:$B$11)*$L9+($L9>='PY-15 Tax Slab Config'!$B$8:$B$11)*'PY-15 Tax Slab Config'!$B$8:$B$11-'PY-15 Tax Slab Config'!$A$8:$A$11)*'PY-15 Tax Slab Config'!$C$8:$C$11),2)) -> 3450 | S9: =IF(B9="","",L9-N(M9)-N(N9)-N(O9)-R9) -> 29550 | T9: =IF(B9="","",IF(N(O9)>N(Q9),"EXCEEDS APPROVED LIMIT",IF(N(O9)>N(P9),"EXCEEDS BALANCE","OK"))) -> OK
A10: 2 | B10: EMP-000102 | C10: Example Employee B | D10: Example Father B | E10: Second Unit A | F10: Permanent | G10: 25000 | H10: 20 | I10: 150 | J10: =IF(B10="","",ROUND(N(H10)*N(I10),2)) -> 3000 | K10: 2000 | L10: =IF(B10="","",N(G10)+N(J10)+N(K10)) -> 30000 | M10: 0 | N10: 0 | O10: 0 | P10: 0 | Q10: 0 | R10: =IF(B10="","",ROUND(SUMPRODUCT(('PY-15 Tax Slab Config'!$A$8:$A$11<$L10)*(($L10<'PY-15 Tax Slab Config'!$B$8:$B$11)*$L10+($L10>='PY-15 Tax Slab Config'!$B$8:$B$11)*'PY-15 Tax Slab Config'!$B$8:$B$11-'PY-15 Tax Slab Config'!$A$8:$A$11)*'PY-15 Tax Slab Config'!$C$8:$C$11),2)) -> 1900 | S10: =IF(B10="","",L10-N(M10)-N(N10)-N(O10)-R10) -> 28100 | T10: =IF(B10="","",IF(N(O10)>N(Q10),"EXCEEDS APPROVED LIMIT",IF(N(O10)>N(P10),"EXCEEDS BALANCE","OK"))) -> OK
A11: 3 | B11: EMP-000103 | C11: Example Employee C | D11: Example Father C | E11: Administration | F11: Temporary | G11: 15000 | H11: 0 | I11: 0 | J11: =IF(B11="","",ROUND(N(H11)*N(I11),2)) -> 0 | K11: 0 | L11: =IF(B11="","",N(G11)+N(J11)+N(K11)) -> 15000 | M11: 0 | N11: 0 | O11: 0 | P11: 0 | Q11: 0 | R11: =IF(B11="","",ROUND(SUMPRODUCT(('PY-15 Tax Slab Config'!$A$8:$A$11<$L11)*(($L11<'PY-15 Tax Slab Config'!$B$8:$B$11)*$L11+($L11>='PY-15 Tax Slab Config'!$B$8:$B$11)*'PY-15 Tax Slab Config'!$B$8:$B$11-'PY-15 Tax Slab Config'!$A$8:$A$11)*'PY-15 Tax Slab Config'!$C$8:$C$11),2)) -> 400 | S11: =IF(B11="","",L11-N(M11)-N(N11)-N(O11)-R11) -> 14600 | T11: =IF(B11="","",IF(N(O11)>N(Q11),"EXCEEDS APPROVED LIMIT",IF(N(O11)>N(P11),"EXCEEDS BALANCE","OK"))) -> OK
A12: 4 | B12: EMP-000104 | C12: Example Employee D | D12: Example Father D | E12: Second Unit B | F12: Permanent | G12: 120000 | H12: 0 | I12: 0 | J12: =IF(B12="","",ROUND(N(H12)*N(I12),2)) -> 0 | K12: 10000 | L12: =IF(B12="","",N(G12)+N(J12)+N(K12)) -> 130000 | M12: 0 | N12: 0 | O12: 0 | P12: 0 | Q12: 0 | R12: =IF(B12="","",ROUND(SUMPRODUCT(('PY-15 Tax Slab Config'!$A$8:$A$11<$L12)*(($L12<'PY-15 Tax Slab Config'!$B$8:$B$11)*$L12+($L12>='PY-15 Tax Slab Config'!$B$8:$B$11)*'PY-15 Tax Slab Config'!$B$8:$B$11-'PY-15 Tax Slab Config'!$A$8:$A$11)*'PY-15 Tax Slab Config'!$C$8:$C$11),2)) -> 14900 | S12: =IF(B12="","",L12-N(M12)-N(N12)-N(O12)-R12) -> 115100 | T12: =IF(B12="","",IF(N(O12)>N(Q12),"EXCEEDS APPROVED LIMIT",IF(N(O12)>N(P12),"EXCEEDS BALANCE","OK"))) -> OK
A13: 5 | J13: =IF(B13="","",ROUND(N(H13)*N(I13),2)) | L13: =IF(B13="","",N(G13)+N(J13)+N(K13)) | R13: =IF(B13="","",ROUND(SUMPRODUCT(('PY-15 Tax Slab Config'!$A$8:$A$11<$L13)*(($L13<'PY-15 Tax Slab Config'!$B$8:$B$11)*$L13+($L13>='PY-15 Tax Slab Config'!$B$8:$B$11)*'PY-15 Tax Slab Config'!$B$8:$B$11-'PY-15 Tax Slab Config'!$A$8:$A$11)*'PY-15 Tax Slab Config'!$C$8:$C$11),2)) | S13: =IF(B13="","",L13-N(M13)-N(N13)-N(O13)-R13) | T13: =IF(B13="","",IF(N(O13)>N(Q13),"EXCEEDS APPROVED LIMIT",IF(N(O13)>N(P13),"EXCEEDS BALANCE","OK")))
A14: 6 | J14: =IF(B14="","",ROUND(N(H14)*N(I14),2)) | L14: =IF(B14="","",N(G14)+N(J14)+N(K14)) | R14: =IF(B14="","",ROUND(SUMPRODUCT(('PY-15 Tax Slab Config'!$A$8:$A$11<$L14)*(($L14<'PY-15 Tax Slab Config'!$B$8:$B$11)*$L14+($L14>='PY-15 Tax Slab Config'!$B$8:$B$11)*'PY-15 Tax Slab Config'!$B$8:$B$11-'PY-15 Tax Slab Config'!$A$8:$A$11)*'PY-15 Tax Slab Config'!$C$8:$C$11),2)) | S14: =IF(B14="","",L14-N(M14)-N(N14)-N(O14)-R14) | T14: =IF(B14="","",IF(N(O14)>N(Q14),"EXCEEDS APPROVED LIMIT",IF(N(O14)>N(P14),"EXCEEDS BALANCE","OK")))
A15: 7 | J15: =IF(B15="","",ROUND(N(H15)*N(I15),2)) | L15: =IF(B15="","",N(G15)+N(J15)+N(K15)) | R15: =IF(B15="","",ROUND(SUMPRODUCT(('PY-15 Tax Slab Config'!$A$8:$A$11<$L15)*(($L15<'PY-15 Tax Slab Config'!$B$8:$B$11)*$L15+($L15>='PY-15 Tax Slab Config'!$B$8:$B$11)*'PY-15 Tax Slab Config'!$B$8:$B$11-'PY-15 Tax Slab Config'!$A$8:$A$11)*'PY-15 Tax Slab Config'!$C$8:$C$11),2)) | S15: =IF(B15="","",L15-N(M15)-N(N15)-N(O15)-R15) | T15: =IF(B15="","",IF(N(O15)>N(Q15),"EXCEEDS APPROVED LIMIT",IF(N(O15)>N(P15),"EXCEEDS BALANCE","OK")))
A16: 8 | J16: =IF(B16="","",ROUND(N(H16)*N(I16),2)) | L16: =IF(B16="","",N(G16)+N(J16)+N(K16)) | R16: =IF(B16="","",ROUND(SUMPRODUCT(('PY-15 Tax Slab Config'!$A$8:$A$11<$L16)*(($L16<'PY-15 Tax Slab Config'!$B$8:$B$11)*$L16+($L16>='PY-15 Tax Slab Config'!$B$8:$B$11)*'PY-15 Tax Slab Config'!$B$8:$B$11-'PY-15 Tax Slab Config'!$A$8:$A$11)*'PY-15 Tax Slab Config'!$C$8:$C$11),2)) | S16: =IF(B16="","",L16-N(M16)-N(N16)-N(O16)-R16) | T16: =IF(B16="","",IF(N(O16)>N(Q16),"EXCEEDS APPROVED LIMIT",IF(N(O16)>N(P16),"EXCEEDS BALANCE","OK")))
A17: 9 | J17: =IF(B17="","",ROUND(N(H17)*N(I17),2)) | L17: =IF(B17="","",N(G17)+N(J17)+N(K17)) | R17: =IF(B17="","",ROUND(SUMPRODUCT(('PY-15 Tax Slab Config'!$A$8:$A$11<$L17)*(($L17<'PY-15 Tax Slab Config'!$B$8:$B$11)*$L17+($L17>='PY-15 Tax Slab Config'!$B$8:$B$11)*'PY-15 Tax Slab Config'!$B$8:$B$11-'PY-15 Tax Slab Config'!$A$8:$A$11)*'PY-15 Tax Slab Config'!$C$8:$C$11),2)) | S17: =IF(B17="","",L17-N(M17)-N(N17)-N(O17)-R17) | T17: =IF(B17="","",IF(N(O17)>N(Q17),"EXCEEDS APPROVED LIMIT",IF(N(O17)>N(P17),"EXCEEDS BALANCE","OK")))
A18: 10 | J18: =IF(B18="","",ROUND(N(H18)*N(I18),2)) | L18: =IF(B18="","",N(G18)+N(J18)+N(K18)) | R18: =IF(B18="","",ROUND(SUMPRODUCT(('PY-15 Tax Slab Config'!$A$8:$A$11<$L18)*(($L18<'PY-15 Tax Slab Config'!$B$8:$B$11)*$L18+($L18>='PY-15 Tax Slab Config'!$B$8:$B$11)*'PY-15 Tax Slab Config'!$B$8:$B$11-'PY-15 Tax Slab Config'!$A$8:$A$11)*'PY-15 Tax Slab Config'!$C$8:$C$11),2)) | S18: =IF(B18="","",L18-N(M18)-N(N18)-N(O18)-R18) | T18: =IF(B18="","",IF(N(O18)>N(Q18),"EXCEEDS APPROVED LIMIT",IF(N(O18)>N(P18),"EXCEEDS BALANCE","OK")))
A19: 11 | J19: =IF(B19="","",ROUND(N(H19)*N(I19),2)) | L19: =IF(B19="","",N(G19)+N(J19)+N(K19)) | R19: =IF(B19="","",ROUND(SUMPRODUCT(('PY-15 Tax Slab Config'!$A$8:$A$11<$L19)*(($L19<'PY-15 Tax Slab Config'!$B$8:$B$11)*$L19+($L19>='PY-15 Tax Slab Config'!$B$8:$B$11)*'PY-15 Tax Slab Config'!$B$8:$B$11-'PY-15 Tax Slab Config'!$A$8:$A$11)*'PY-15 Tax Slab Config'!$C$8:$C$11),2)) | S19: =IF(B19="","",L19-N(M19)-N(N19)-N(O19)-R19) | T19: =IF(B19="","",IF(N(O19)>N(Q19),"EXCEEDS APPROVED LIMIT",IF(N(O19)>N(P19),"EXCEEDS BALANCE","OK")))
A20: 12 | J20: =IF(B20="","",ROUND(N(H20)*N(I20),2)) | L20: =IF(B20="","",N(G20)+N(J20)+N(K20)) | R20: =IF(B20="","",ROUND(SUMPRODUCT(('PY-15 Tax Slab Config'!$A$8:$A$11<$L20)*(($L20<'PY-15 Tax Slab Config'!$B$8:$B$11)*$L20+($L20>='PY-15 Tax Slab Config'!$B$8:$B$11)*'PY-15 Tax Slab Config'!$B$8:$B$11-'PY-15 Tax Slab Config'!$A$8:$A$11)*'PY-15 Tax Slab Config'!$C$8:$C$11),2)) | S20: =IF(B20="","",L20-N(M20)-N(N20)-N(O20)-R20) | T20: =IF(B20="","",IF(N(O20)>N(Q20),"EXCEEDS APPROVED LIMIT",IF(N(O20)>N(P20),"EXCEEDS BALANCE","OK")))
A21: TOTAL | G21: =SUM(G9:G20) -> 200000 | H21: =SUM(H9:H20) -> 30 | J21: =SUM(J9:J20) -> 5500 | K21: =SUM(K9:K20) -> 15000 | L21: =SUM(L9:L20) -> 220500 | M21: =SUM(M9:M20) -> 2000 | N21: =SUM(N9:N20) -> 500 | O21: =SUM(O9:O20) -> 10000 | R21: =SUM(R9:R20) -> 20650 | S21: =SUM(S9:S20) -> 187350
A23: PREPARED BY (Payroll Officer) | H23: REVIEWED / APPROVED BY (Payroll Department Head) | P23: VERIFIED BY (Internal Control & Audit)
A24: Name: | H24: Name: | P24: Name:
A25: Position: | H25: Position: | P25: Position:
A26: Signature: | H26: Signature: | P26: Signature:
A27: Date: | H27: Date: | P27: Date:
A29: NOTES FOR DEVELOPERS
A30: 1. Net Pay = Basic Salary + Overtime Pay + Other Allowances - Rent - Electricity - Advance Deduction - Income Tax (approved formula). Everything in grey is system-calculated; the Payroll Officer keys only allowances, rent, electricity and the advance deduction.
A31: 2. Income Tax is auto-calculated from the configurable slab table (PY-15). Gross Taxable Income here = Basic + Overtime + Other Allowances; rent and electricity are treated as salary deductions, not taxable compensation (per the approved report). Confirm which allowance types are taxable per ARD rules.
A32: 3. Overtime Pay = overtime hours from the finalized timesheet x applicable overtime rate. The report does not say where the rate comes from (per employee, per grade or a single rate) - confirm and make it a configurable parameter.
A33: 4. Advance Outstanding and Approved Monthly Limit are pushed by the system from the advance ledger (PY-08); the Officer's deduction must stay within both. Wages-based workers are NOT on this sheet (see PY-10).
A34: 5. The Executive Director and Directors have no system access. Their approvals (leave letters, advances, the printed payroll sheet) are physical, filed in hard copy and recorded in the ERP by staff, so no Director signature block appears on these forms. The printed IC-verified sheet is signed physically by the Director outside the ERP.

Sheet PY-10 Wages-Based Entry
A1: [Corporation logo] | C1: NORTH COAL STATE OWNED CORPORATION
C2: WAGES-BASED WORKERS - COLLECTIVE CASH WAGES ENTRY
C3: Form PY-10 | Version 1.0 | One total per Second Unit per period - workers are not recorded as named individuals
A5: Payroll Period Ref. | C5: PAY-2026-10-WG | D5: Payroll Month | E5: October 2026
A7: No. | B7: Second Unit | C7: Period | D7: Entered By (designated Second Unit person) | E7: Total Cash Wages (AFN) | F7: Payroll Officer Confirmed?
A8: 1 | B8: Second Unit A | C8: October 2026 | D8: SU-A-DESIG-01 | E8: 185000 | F8: Yes
A9: 2 | B9: Second Unit B | C9: October 2026 | D9: SU-B-DESIG-01 | E9: 240500 | F9: Yes
A10: 3 | B10: Second Unit C | C10: October 2026 | D10: SU-C-DESIG-01 | E10: 96000 | F10: No
A11: 4
A12: 5
A13: 6
A14: TOTAL CASH WAGES (AFN) | E14: =SUM(E8:E13) -> 521500
A15: Confirmed by Payroll Officer (AFN) | E15: =SUMIF(F8:F13,"Yes",E8:E13) -> 425500
A16: Awaiting confirmation (AFN) | E16: =E14-E15 -> 96000
A18: Automatic Accounting | C18: Dr Wages Expense Account / Cr Cash Account (cash payment)
A20: ENTERED BY (Designated Second Unit Person) | D20: CONFIRMED BY (Payroll Officer) | E20: VERIFIED BY (Internal Control & Audit)
A21: Name: | D21: Name: | E21: Name:
A22: Position: | D22: Position: | E22: Position:
A23: Signature: | D23: Signature: | E23: Signature:
A24: Date: | D24: Date: | E24: Date:
A26: NOTES FOR DEVELOPERS
A27: 1. Workers' wages are recorded as a collective cash expense per Second Unit per period by the designated Second Unit person; the Payroll Officer reviews and confirms each unit total before it enters the consolidated payroll record.
A28: 2. Internal Control verifies the totals per Second Unit as part of the single consolidated payroll verification (PY-12).
A29: 3. Name, position and date may be pre-filled by the system from the Control Log; signatures are by hand so the printed form can be archived in the hard file.

Sheet PY-11 Payroll Summary
A1: [Corporation logo] | C1: NORTH COAL STATE OWNED CORPORATION
C2: CONSOLIDATED PAYROLL SUMMARY - ALL STAFF CATEGORIES
C3: Single record routed to Internal Control for ONE consolidated verification (AFN)
A5: Payroll Month | B5: October 2026 | E5: Status | G5: Approved by Dept Head - routed to IC
A7: Staff Category | B7: Headcount | C7: Gross Taxable Income | D7: Rent Deduction | E7: Electricity Deduction | F7: Advance Deductions | G7: Income Tax Withheld | H7: Net Pay / Cash Wages
A8: Permanent employees | B8: =COUNTIF('PY-09 Payroll Calculation'!$F$9:$F$20,"Permanent") -> 3 | C8: =SUMIF('PY-09 Payroll Calculation'!$F$9:$F$20,"Permanent",'PY-09 Payroll Calculation'!$L$9:$L$20) -> 205500 | D8: =SUMIF('PY-09 Payroll Calculation'!$F$9:$F$20,"Permanent",'PY-09 Payroll Calculation'!$M$9:$M$20) -> 2000 | E8: =SUMIF('PY-09 Payroll Calculation'!$F$9:$F$20,"Permanent",'PY-09 Payroll Calculation'!$N$9:$N$20) -> 500 | F8: =SUMIF('PY-09 Payroll Calculation'!$F$9:$F$20,"Permanent",'PY-09 Payroll Calculation'!$O$9:$O$20) -> 10000 | G8: =SUMIF('PY-09 Payroll Calculation'!$F$9:$F$20,"Permanent",'PY-09 Payroll Calculation'!$R$9:$R$20) -> 20250 | H8: =SUMIF('PY-09 Payroll Calculation'!$F$9:$F$20,"Permanent",'PY-09 Payroll Calculation'!$S$9:$S$20) -> 172750
A9: Temporary employees | B9: =COUNTIF('PY-09 Payroll Calculation'!$F$9:$F$20,"Temporary") -> 1 | C9: =SUMIF('PY-09 Payroll Calculation'!$F$9:$F$20,"Temporary",'PY-09 Payroll Calculation'!$L$9:$L$20) -> 15000 | D9: =SUMIF('PY-09 Payroll Calculation'!$F$9:$F$20,"Temporary",'PY-09 Payroll Calculation'!$M$9:$M$20) -> 0 | E9: =SUMIF('PY-09 Payroll Calculation'!$F$9:$F$20,"Temporary",'PY-09 Payroll Calculation'!$N$9:$N$20) -> 0 | F9: =SUMIF('PY-09 Payroll Calculation'!$F$9:$F$20,"Temporary",'PY-09 Payroll Calculation'!$O$9:$O$20) -> 0 | G9: =SUMIF('PY-09 Payroll Calculation'!$F$9:$F$20,"Temporary",'PY-09 Payroll Calculation'!$R$9:$R$20) -> 400 | H9: =SUMIF('PY-09 Payroll Calculation'!$F$9:$F$20,"Temporary",'PY-09 Payroll Calculation'!$S$9:$S$20) -> 14600
A10: Wages-based workers (collective per Second Unit) | B10: n/a | H10: ='PY-10 Wages-Based Entry'!$E$14 -> 521500
A11: TOTAL | B11: =SUM(B8:B9) -> 4 | C11: =SUM(C8:C10) -> 220500 | D11: =SUM(D8:D10) -> 2000 | E11: =SUM(E8:E10) -> 500 | F11: =SUM(F8:F10) -> 10000 | G11: =SUM(G8:G10) -> 20650 | H11: =SUM(H8:H10) -> 708850
A12: Cross-check: Net Pay per payroll sheet total (PY-09) | H12: ='PY-09 Payroll Calculation'!$S$21 -> 187350
A13: Check: Permanent + Temporary net pay agrees to sheet | H13: =IF(ROUND(H8+H9-H12,2)=0,"AGREES","DIFFERENCE") -> AGREES
A15: PREPARED BY (Payroll Officer) | B15: REVIEWED / APPROVED BY (Payroll Department Head) | F15: VERIFIED BY (Internal Control & Audit)
A16: Name: | B16: Name: | F16: Name:
A17: Position: | B17: Position: | F17: Position:
A18: Signature: | B18: Signature: | F18: Signature:
A19: Date: | B19: Date: | F19: Date:
A21: NOTES FOR DEVELOPERS
A22: 1. One consolidated verification covers all three categories simultaneously before ANY accounting entry is posted or ANY payment is processed.
A23: 2. Cross-sheet formulas read from PY-09 and PY-10; example figures are illustrative.
A24: 3. The Executive Director and Directors have no system access. Their approvals (leave letters, advances, the printed payroll sheet) are physical, filed in hard copy and recorded in the ERP by staff, so no Director signature block appears on these forms.

Sheet PY-12 IC Payroll Verification
A1: [Corporation logo] | C1: NORTH COAL STATE OWNED CORPORATION
C2: INTERNAL CONTROL VERIFICATION RECORD - CONSOLIDATED PAYROLL
C3: Form PY-12 | Version 1.0 | Mandatory single gate at the end of payroll preparation
A5: Verification No. | C5: ICV-2026-000427 | D5: Date Received by IC | E5: 46323
A6: Payroll Period Ref. | C6: PAY-2026-10 | D6: Payroll Month | E6: October 2026
A7: Categories Covered | C7: Permanent, Temporary, Wages-based | D7: Re-verification Round | E7: 1
A9: VERIFICATION CHECKLIST
A10: No. | B10: Check | E10: Result | F10: Document Ref. / Comment
A11: 1 | B11: Timesheet data is consistent with other available records | E11: Yes
A12: 2 | B12: Leave days recorded are within approved balances | E12: Yes
A13: 3 | B13: Field work and official travel entries are properly recorded | E13: Yes
A14: 4 | B14: Overtime hours and calculations reviewed | E14: Yes
A15: 5 | B15: Rent and electricity deductions accurately recorded and deducted from net pay | E15: Yes
A16: 6 | B16: Advance deductions are within approved limits and outstanding balances updated correctly | E16: Yes
A17: 7 | B17: Income tax computation is accurate per applicable Afghan tax law | E17: Yes
A18: 8 | B18: Wages-based worker totals verified per Second Unit | E18: Yes
A20: Outcome (system rule) | C20: =IF(COUNTBLANK(E11:E18)>0,"INCOMPLETE",IF(COUNTIF(E11:E18,"No")>0,"REJECT","VERIFY")) -> VERIFY
A21: Final Outcome (IC decision) | C21: Verified | D21: Decision Date | E21: 46324
A22: IC Comments (mandatory if Rejected)
A23: If Rejected | C23: Notification with IC comments to Payroll Dept Head -> Head unlocks -> Payroll Officer notified, corrects, resubmits -> Head re-approves -> back to IC for re-verification.
A24: If Verified | C24: System posts all accounting entries automatically (PY-19) -> payroll sheet available for printing -> printed copy to Director for physical signature (outside ERP) -> confirmation recorded by Payroll staff -> bank transfers processed -> payslips generated.
A26: PREPARED BY (Payroll Officer) | D26: REVIEWED / APPROVED BY (Payroll Department Head) | E26: VERIFIED BY (Internal Control & Audit)
A27: Name: | D27: Name: | E27: Name:
A28: Position: | D28: Position: | E28: Position:
A29: Signature: | D29: Signature: | E29: Signature:
A30: Date: | D30: Date: | E30: Date:
A32: NOTES FOR DEVELOPERS
A33: 1. IC has read-only access to all payroll and timesheet records; it can only Verify or Reject (comments mandatory on rejection). Every verification and rejection is written to the Control Log (FA-18).
A34: 2. The Executive Director and Directors have no system access. Their approvals (leave letters, advances, the printed payroll sheet) are physical, filed in hard copy and recorded in the ERP by staff, so no Director signature block appears on these forms.

Sheet PY-13 Payslip
A1: [Corporation logo] | C1: NORTH COAL STATE OWNED CORPORATION
C2: EMPLOYEE PAYSLIP
C3: Digital PDF payslip | Version 1.0 | Downloadable by the Payroll Department Head or Payroll Officer on demand
A5: EMPLOYEE AND PERIOD
A6: Employee Name | C6: Example Employee A | D6: Father's Name | E6: Example Father A
A7: Position | C7: Finance Officer | D7: Department | E7: Finance
A8: Payroll Month and Year | C8: October 2026 | D8: Payroll Period Ref. | E8: PAY-2026-10-HQ
A10: EARNINGS
A11: Description | E11: Amount (AFN)
A12: Basic Salary | E12: 40000
A13: Overtime Pay | E13: 2500
A14: Other Allowances | E14: 3000
A15: GROSS TAXABLE INCOME | E15: =SUM(E12:E14) -> 45500
A17: DEDUCTIONS
A18: Home Rent Deduction | E18: 2000
A19: Electricity Deduction | E19: 500
A20: Advance Deduction | E20: 10000
A21: Income Tax | E21: 3450
A22: TOTAL DEDUCTIONS | E22: =SUM(E18:E21) -> 15950
A24: NET PAY | E24: =E15-E22 -> 29550
A26: NOTES FOR DEVELOPERS
A27: 1. Payslip content is exactly as approved: name, father's name, position, department, month and year, basic salary, overtime and allowances, gross taxable income, rent / electricity / advance / income tax deductions, net pay, corporation name and logo, payroll period reference.
A28: 2. Generated for each Permanent and Temporary employee after payroll completes; PDF only. Example figures match employee 1 on PY-09. No signature block - it is a system-generated digital document.

Sheet PY-14 Bank Transfer List
A1: [Corporation logo] | C1: NORTH COAL STATE OWNED CORPORATION
C2: SALARY BANK TRANSFER LIST
C3: Supporting template derived from the current bank transfer lists - generated from the IC-verified payroll
A5: Payroll Period Ref. | C5: PAY-2026-10-HQ | D5: Paying Bank Account | E5: Example Bank - Expense Account
A7: No. | B7: Employee ID | C7: Employee Name | D7: Bank Name | E7: Account Number (masked example) | F7: Net Pay (AFN)
A8: 1 | B8: EMP-000101 | C8: Example Employee A | D8: Example Bank | E8: XXXX-0001 | F8: ='PY-09 Payroll Calculation'!S9 -> 29550
A9: 2 | B9: EMP-000102 | C9: Example Employee B | D9: Example Bank | E9: XXXX-0002 | F9: ='PY-09 Payroll Calculation'!S10 -> 28100
A10: 3 | B10: EMP-000103 | C10: Example Employee C | D10: Example Bank | E10: XXXX-0003 | F10: ='PY-09 Payroll Calculation'!S11 -> 14600
A11: 4 | B11: EMP-000104 | C11: Example Employee D | D11: Example Bank | E11: XXXX-0004 | F11: ='PY-09 Payroll Calculation'!S12 -> 115100
A12: 5
A13: 6
A14: 7
A15: 8
A16: 9
A17: 10
A18: TOTAL TO BE TRANSFERRED (AFN) | F18: =SUM(F8:F17) -> 187350
A20: PREPARED BY (Payroll Officer) | D20: REVIEWED BY (Payroll Department Head) | E20: VERIFIED BY (Internal Control & Audit)
A21: Name: | D21: Name: | E21: Name:
A22: Position: | D22: Position: | E22: Position:
A23: Signature: | D23: Signature: | E23: Signature:
A24: Date: | D24: Date: | E24: Date:
A26: NOTES FOR DEVELOPERS
A27: 1. Supporting template: the approved report says payments are processed by bank transfer after IC verification and Director sign-off but does not define the bank list layout; this follows the manual list used today (employee, account, net pay).
A28: 2. When the bank confirms processing the system posts Dr Salaries Payable / Cr Bank Account (PY-19). Bank account numbers shown are masked examples only.
A29: 3. The Executive Director and Directors have no system access. Their approvals (leave letters, advances, the printed payroll sheet) are physical, filed in hard copy and recorded in the ERP by staff, so no Director signature block appears on these forms.

Sheet PY-15 Tax Slab Config
A1: [Corporation logo] | C1: NORTH COAL STATE OWNED CORPORATION
C2: INCOME TAX SLAB CONFIGURATION (MONTHLY WAGE WITHHOLDING)
C3: Parameter table - must be editable without code changes so payroll survives future tax-rule changes
A5: Illustrative rates from a secondary source (Rivermate Afghanistan guide, valid 16 February 2026). VERIFY against current Afghanistan Revenue Department (ARD) rules before go-live. Slabs are marginal on monthly gross.
A7: From (AFN / month) | B7: To (AFN / month) | C7: Rate on Excess | D7: Effective From | E7: Effective To | F7: Status | G7: Cumulative Tax at Lower Bound (check)
A8: 0 | B8: 5000 | C8: 0 | D8: 46023 | F8: Active | G8: =0 -> 0
A9: 5000 | B9: 12500 | C9: 0.02 | D9: 46023 | F9: Active | G9: =G8+(B8-A8)*C8 -> 0
A10: 12500 | B10: 100000 | C10: 0.1 | D10: 46023 | F10: Active | G10: =G9+(B9-A9)*C9 -> 150
A11: 100000 | B11: 999999999 | C11: 0.2 | D11: 46023 | F11: Active | G11: =G10+(B10-A10)*C10 -> 8900
A13: TEST CALCULATOR
A14: Monthly gross taxable income (AFN) | C14: 130000
A15: Tax withheld (AFN) | C15: =ROUND(SUMPRODUCT((A8:A11<C14)*((C14<B8:B11)*C14+(C14>=B8:B11)*B8:B11-A8:A11)*C8:C11),2) -> 14900 | E15: =IF(C15=C16,"Test passes - formula agrees with the published table","CHECK SLAB TABLE") -> Test passes - formula agrees with the published table
A16: Expected (ARD table: 8,900 + 20% x excess over 100,000) | C16: =ROUND(G11+(C14-A11)*C11,2) -> 14900
A18: NOTES FOR DEVELOPERS
A19: 1. Tax is "auto-calculated per applicable Afghan tax law and current ARD slab rates" and the Payroll Manager asked for flexibility if rules change: slabs, effective dates and status must be maintained as data, never hard-coded.
A20: 2. The same secondary source states taxable income includes overtime and ALL cash allowances irrespective of purpose, and that per diems for work travel are subject to withholding from 16 February 2026 - relevant to the "Other Allowances" and "Official Travel" handling. Confirm with ARD.
A21: 3. The same source lists a separate social contribution; the approved report has no such deduction. Confirm whether it applies to North Coal. Who may edit this table is not specified in the report - confirm.

Sheet PY-16 Tax Withholding Register
A1: [Corporation logo] | C1: NORTH COAL STATE OWNED CORPORATION
C2: TAX WITHHOLDING AND REMITTANCE REGISTER
C3: Running record of tax withheld and remitted to ARD for each period
A5: Remittance Deadline (days after month end) | C5: 10 | E5: Report As-of Date | G5: 46331
A6: Deadline taken from a secondary source (Rivermate, 16 Feb 2026: within 10 days after the month in which wages were paid). Verify with ARD - it is a parameter, not a constant.
A8: Payroll Month | B8: Tax Withheld (AFN) | C8: Remittance Due Date | D8: Amount Remitted (AFN) | E8: Remittance Date | F8: Payment Reference | G8: Outstanding (AFN) | H8: Status (auto)
A9: 46235 | B9: 428000 | C9: =IF(A9="","",EOMONTH(A9,0)+$C$5) -> 46275 | D9: 428000 | E9: 46273 | F9: PV-000096 | G9: =IF(A9="","",B9-N(D9)) -> 0 | H9: =IF(A9="","",IF(G9<=0,"Remitted in full",IF($G$5>C9,"OVERDUE","Due - not yet late"))) -> Remitted in full
A10: 46266 | B10: 455500 | C10: =IF(A10="","",EOMONTH(A10,0)+$C$5) -> 46305 | D10: 400000 | E10: 46304 | F10: PV-000121 | G10: =IF(A10="","",B10-N(D10)) -> 55500 | H10: =IF(A10="","",IF(G10<=0,"Remitted in full",IF($G$5>C10,"OVERDUE","Due - not yet late"))) -> OVERDUE
A11: 46296 | B11: 462300 | C11: =IF(A11="","",EOMONTH(A11,0)+$C$5) -> 46336 | G11: =IF(A11="","",B11-N(D11)) -> 462300 | H11: =IF(A11="","",IF(G11<=0,"Remitted in full",IF($G$5>C11,"OVERDUE","Due - not yet late"))) -> Due - not yet late
C12: =IF(A12="","",EOMONTH(A12,0)+$C$5) | G12: =IF(A12="","",B12-N(D12)) | H12: =IF(A12="","",IF(G12<=0,"Remitted in full",IF($G$5>C12,"OVERDUE","Due - not yet late")))
C13: =IF(A13="","",EOMONTH(A13,0)+$C$5) | G13: =IF(A13="","",B13-N(D13)) | H13: =IF(A13="","",IF(G13<=0,"Remitted in full",IF($G$5>C13,"OVERDUE","Due - not yet late")))
C14: =IF(A14="","",EOMONTH(A14,0)+$C$5) | G14: =IF(A14="","",B14-N(D14)) | H14: =IF(A14="","",IF(G14<=0,"Remitted in full",IF($G$5>C14,"OVERDUE","Due - not yet late")))
C15: =IF(A15="","",EOMONTH(A15,0)+$C$5) | G15: =IF(A15="","",B15-N(D15)) | H15: =IF(A15="","",IF(G15<=0,"Remitted in full",IF($G$5>C15,"OVERDUE","Due - not yet late")))
C16: =IF(A16="","",EOMONTH(A16,0)+$C$5) | G16: =IF(A16="","",B16-N(D16)) | H16: =IF(A16="","",IF(G16<=0,"Remitted in full",IF($G$5>C16,"OVERDUE","Due - not yet late")))
A17: TOTAL | B17: =SUM(B9:B16) -> 1345800 | D17: =SUM(D9:D16) -> 828000 | G17: =SUM(G9:G16) -> 517800
A19: NOTES FOR DEVELOPERS
A20: 1. "Tax Withholding Report" (consolidated, for tax authority submission) is built from this register. Tax Payable to Government is credited at payroll posting; remittance is made through a Finance Payment Voucher.
A21: 2. The As-of Date is an input (not TODAY()) so the printed report is reproducible. Example amounts are illustrative.

Sheet PY-17 Correction Request
A1: [Corporation logo] | C1: NORTH COAL STATE OWNED CORPORATION
C2: OFFICER CORRECTION REQUEST - PAYROLL
C3: Form PY-17 | Version 1.0 | Same standard form as FA-11, module set to Payroll
A5: A. REQUEST (raised by Payroll Officer)
A6: Request No. | C6: CR-2026-000058 | D6: Date Raised | E6: 46322.406
A7: Module | C7: Payroll | D7: Second Unit / HQ | E7: HQ
A8: Entry Type | C8: Payroll Calculation Sheet | D8: Entry Reference | E8: PAY-2026-10-HQ / EMP-000101
A9: Raised By (Officer) | C9: PAY-OFF-01 | D9: Entry Status at Request | E9: Submitted - before IC verification
A10: Description of Error | C10: Electricity deduction keyed as 5,000 instead of 500. EXAMPLE DATA.
A11: Required Correction | C11: Change electricity deduction from 5,000 to 500.
A12: Justification | C12: Electricity usage statement shows 500.
A14: B. PAYROLL DEPARTMENT HEAD DECISION (notified automatically on submission)
A15: Decision | C15: Approved | D15: Decision Date / Time | E15: 46322.438
A16: Reason (recorded if Rejected)
A17: Entry Unlocked | C17: Yes - Officer notified automatically | D17: Corrected Entry Ref. | E17: PAY-2026-10-HQ (rev. 2)
A19: C. CONTROL LOG - PERMANENTLY RECORDED AND VISIBLE TO INTERNAL CONTROL
A20: Original entry | D20: Recorded
A21: Correction request | D21: Recorded
A22: Department Head decision | D22: Recorded
A23: Corrected entry | D23: Recorded
A25: REQUESTED BY (Payroll Officer) | D25: DECIDED BY (Payroll Department Head)
A26: Name: | D26: Name:
A27: Position: | D27: Position:
A28: Signature: | D28: Signature:
A29: Date: | D29: Date:
A31: NOTES FOR DEVELOPERS
A32: 1. Applies to entries already submitted and not caught by IC at the final payroll stage. The Officer can never modify or delete a submitted entry directly.
A33: 2. IC rejections of the consolidated payroll use the unlock loop in PY-12, not this form. Every step is written to the Control Log (layout FA-18).

Sheet PY-18 Approval Matrix
A1: [Corporation logo] | C1: NORTH COAL STATE OWNED CORPORATION
C2: PAYROLL APPROVAL AND VERIFICATION MATRIX
C3: Who prepares, approves and verifies each form; the Executive Director has no system role
A5: Form | B5: Initiated / Prepared By | C5: Department Head Action | D5: Director (physical, outside system) | E5: Other Approver | F5: Internal Control (read-only) | G5: Automatic System Action
A6: PY-01 Employee Record | B6: Not specified in report (HR or Payroll) | C6: Not specified | D6: None | E6: None | F6: Read-only view | G6: Date-effective history kept
A7: PY-03 Leave Record | B7: Employee (physical letter); Department Head records | C7: Records leave in system | D7: Approves letter physically; confirmation filed | E7: None | F7: Checks balances in IC review | G7: Balance check; updates timesheet; enforces exceptional-leave rules
A8: PY-05 Timesheet | B8: Employee / designated officer / Second Unit designated person | C8: Reviews and finalizes at month end | D8: None | E8: None | F8: Checks vs other records | G8: Locks timesheet; routes to Payroll
A9: PY-07 Salary Advance | B9: Department Head submits | C9: Confirms in system | D9: Approval recorded by staff | E9: Finance Department Head authorizes | F9: None | G9: Creates advance balance and monthly limit after PV payment
A10: PY-09 Payroll Calculation | B10: Payroll Officer | C10: Payroll Dept Head reviews and approves | D10: Signs printed sheet AFTER IC verification | E10: None | F10: Mandatory consolidated Verify / Reject | G10: Auto tax; auto net pay; pro-rata; posts entries after IC
A11: PY-10 Wages-Based Entry | B11: Designated Second Unit person | C11: None | D11: None | E11: Payroll Officer confirms each unit total | F11: Verifies totals per Second Unit | G11: Posts Dr Wages Expense / Cr Cash after IC
A12: PY-13 Payslip | B12: System-generated | C12: Dept Head or Payroll Officer can download | D12: None | E12: None | F12: None | G12: PDF payslip for each Permanent / Temporary employee
A13: PY-17 Correction Request | B13: Payroll Officer | C13: Approves / rejects; unlocks if approved | D13: None | E13: None | F13: Sees full trail in Control Log | G13: Notifies Officer on unlock; logs every step

Sheet PY-19 Accounting Entries
A1: [Corporation logo] | C1: NORTH COAL STATE OWNED CORPORATION
C2: ACCOUNTING ENTRIES - DEVELOPER REFERENCE (PAYROLL)
C3: Posted automatically in the background after IC verification - no manual input from Finance staff
A5: # | B5: Trigger Event | C5: Debit | D5: Credit | E5: Posting Basis
A6: 1 | B6: Permanent / Temporary staff payroll posting | C6: Salary Expense Account | D6: Salaries Payable Account | E6: After IC verification of the consolidated payroll
A7: 2 | B7: Income tax withheld | C7: Salary Expense Account | D7: Tax Payable to Government Account | E7: After IC verification
A8: 3 | B8: Advance deduction applied | C8: Salaries Payable Account | D8: Employee Advance Account | E8: After IC verification; reduces outstanding advance balance
A9: 4 | B9: Salary payment via bank transfer | C9: Salaries Payable Account | D9: Bank Account | E9: After bank processing
A10: 5 | B10: Wages-based workers (cash payment) | C10: Wages Expense Account | D10: Cash Account | E10: After IC verification of Second Unit totals
A12: NOTES FOR DEVELOPERS
A13: 1. Entries are reproduced exactly as approved. The report does not state the AMOUNT basis of each line (gross vs net of tax, rent, electricity and advance). Rent and electricity deductions have no posting listed. Confirm the amount basis and these two items with the report owner before development.
A14: 2. Salaries are recognized as an expense in the period earned, not when paid (accrual basis). Tax withheld is remitted to ARD within the legal timeframe (see PY-16).

Sheet PY-20 Reports Spec
A1: [Corporation logo] | C1: NORTH COAL STATE OWNED CORPORATION
C2: REQUIRED REPORTS - PAYROLL
C3: All reports use the standard header/footer shown in FA-16
A5: # | B5: Report | C5: Frequency | D5: Filter Options | E5: Export
A6: 1 | B6: Consolidated Payroll Summary | C6: On demand | D6: Custom date range, by HQ / Second Unit, by department | E6: PDF + Excel
A7: 2 | B7: Digital Payslips | C7: On demand | D7: Custom date range, per employee | E7: PDF + Excel
A8: 3 | B8: Leave Balance Report | C8: On demand | D8: Custom date range, per employee, per department | E8: PDF + Excel
A9: 4 | B9: Timesheet Summary Report | C9: On demand | D9: Custom date range, per department, per Second Unit | E9: PDF + Excel
A10: 5 | B10: Employee Advance Ledger | C10: On demand | D10: Custom date range, per employee (showing outstanding balances) | E10: PDF + Excel
A11: 6 | B11: Tax Withholding Report | C11: On demand | D11: Custom date range, consolidated for tax authority submission | E11: PDF + Excel
A12: 7 | B12: Control Log / Audit Trail | C12: On demand | D12: Custom date range, by user, action type (tracks all unlocks/corrections) | E12: PDF + Excel
A13: 8 | B13: Internal Control Verification | C13: On demand | D13: Custom date range, by verification outcome (Verified / Rejected) | E13: PDF + Excel
